# Exception Handling in Python

Exception handling is a crucial concept in Python programming, as it allows you to manage and respond to errors that occur during the execution of a program. Without exception handling, an error in a program could cause it to crash. Python provides a robust mechanism for handling exceptions, allowing your program to continue running or exit gracefully when an error occurs.

---

### 1. **Understanding Exceptions**

An exception is an event that disrupts the normal flow of a program's execution. When an exception occurs, Python generates an error message, and the program stops unless the exception is handled.

**Common Exceptions:**

- `SyntaxError`: Raised when the code has invalid syntax.
- `TypeError`: Raised when an operation is performed on an inappropriate data type.
- `ValueError`: Raised when a function receives an argument of the correct type but an inappropriate value.
- `IndexError`: Raised when trying to access an index that is out of range for a sequence (like a list).
- `KeyError`: Raised when trying to access a dictionary key that does not exist.
- `FileNotFoundError`: Raised when trying to open a file that does not exist.
- `ZeroDivisionError`: Raised when attempting to divide by zero.

**Example of an Exception:**

```python
# Example of a ZeroDivisionError
print(10 / 0)  # This will raise a ZeroDivisionError
```

---

### 2. **The `try` and `except` Blocks**

The `try` block lets you test a block of code for errors. The `except` block allows you to handle the error if one occurs. If an exception is raised in the `try` block, the code in the `except` block will be executed.

**Basic Syntax:**

```python
try:
    # Code that may raise an exception
    risky_code()
except SomeException:
    # Code that runs if the exception occurs
    handle_exception()
```

**Example:**

```python
try:
    result = 10 / 0
except ZeroDivisionError:
    print("Error: You cannot divide by zero!")
```

**Output:**

```
Error: You cannot divide by zero!
```

---

### 3. **Catching Multiple Exceptions**

You can handle multiple exceptions by specifying multiple `except` blocks. Each block can catch a different type of exception.

**Example:**

```python
try:
    num = int(input("Enter a number: "))
    result = 10 / num
except ValueError:
    print("Error: That's not a valid number!")
except ZeroDivisionError:
    print("Error: You cannot divide by zero!")
```

**Output Examples:**

```
Enter a number: abc
Error: That's not a valid number!

Enter a number: 0
Error: You cannot divide by zero!
```

---

### 4. **Catching All Exceptions**

If you want to catch any exception, you can use a bare `except` clause. However, this is generally discouraged because it can make debugging difficult by catching unexpected exceptions.

**Example:**

```python
try:
    result = 10 / 0
except:
    print("An error occurred!")
```

**Output:**

```
An error occurred!
```

---

### 5. **Using the `else` Clause**

The `else` block lets you execute code if the `try` block does not raise an exception. This is useful for code that should only run if no errors occur.

**Example:**

```python
try:
    num = int(input("Enter a number: "))
    result = 10 / num
except ZeroDivisionError:
    print("Error: You cannot divide by zero!")
else:
    print(f"Result: {result}")
```

**Output Example:**

```
Enter a number: 2
Result: 5.0
```

---

### 6. **The `finally` Clause**

The `finally` block allows you to execute code, regardless of whether an exception was raised or not. This is often used for cleanup actions, such as closing a file or releasing resources.

**Example:**

```python
try:
    file = open("example.txt", "r")
    content = file.read()
except FileNotFoundError:
    print("Error: The file does not exist!")
finally:
    file.close()
    print("File closed.")
```

**Output:**

```
Error: The file does not exist!
File closed.
```

**Note:** If the file does not exist, the `finally` block still attempts to close it, which can raise another exception. To avoid this, you should ensure the file was successfully opened before closing it:

```python
try:
    file = open("example.txt", "r")
    content = file.read()
except FileNotFoundError:
    print("Error: The file does not exist!")
finally:
    if 'file' in locals() and not file.closed:
        file.close()
        print("File closed.")
```

---

### 7. **Raising Exceptions**

Sometimes, you may want to raise an exception intentionally using the `raise` keyword. This is useful for testing or enforcing certain conditions in your code.

**Example:**

```python
def check_age(age):
    if age < 18:
        raise ValueError("Age must be 18 or older.")
    return "Access granted."

try:
    print(check_age(16))
except ValueError as e:
    print(f"Error: {e}")
```

**Output:**

```
Error: Age must be 18 or older.
```

---

### 8. **Custom Exceptions**

Python allows you to create custom exceptions by defining a new class that inherits from the built-in `Exception` class. This is useful for creating specific exceptions that are meaningful in your application's context.

**Example:**

```python
class InvalidAgeError(Exception):
    """Custom exception for invalid ages."""
    pass

def check_age(age):
    if age < 18:
        raise InvalidAgeError("You must be 18 or older to register.")
    return "Registration successful."

try:
    print(check_age(16))
except InvalidAgeError as e:
    print(f"Error: {e}")
```

**Output:**

```
Error: You must be 18 or older to register.
```

---

### 9. **Chaining Exceptions**

Python allows you to chain exceptions using the `raise ... from` syntax. This is useful when you want to raise a new exception that is caused by a previous exception.

**Example:**

```python
try:
    num = int("not_a_number")
except ValueError as e:
    raise TypeError("Conversion failed") from e
```

**Output:**

```
Traceback (most recent call last):
  File "<stdin>", line 2, in <module>
ValueError: invalid literal for int() with base 10: 'not_a_number'

The above exception was the direct cause of the following exception:

Traceback (most recent call last):
  File "<stdin>", line 4, in <module>
TypeError: Conversion failed
```

---

### 10. **Context Management with `with` and `__enter__`/`__exit__`**

The `with` statement simplifies exception handling by automatically managing resources, such as files or network connections. It works with objects that implement the context management protocol, defined by the `__enter__` and `__exit__` methods.

**Example with `with`:**

```python
try:
    with open("example.txt", "r") as file:
        content = file.read()
        print(content)
except FileNotFoundError:
    print("Error: The file does not exist!")
```

**Custom Context Manager Example:**

```python
class MyContextManager:
    def __enter__(self):
        print("Entering context")
        return self

    def __exit__(self, exc_type, exc_val, exc_tb):
        print("Exiting context")
        if exc_type is not None:
            print(f"An exception occurred: {exc_val}")
        return True  # Suppresses the exception

# Using the custom context manager
with MyContextManager():
    print("Inside the context")
    raise ValueError("Something went wrong")
```

**Output:**

```
Entering context
Inside the context
Exiting context
An exception occurred: Something went wrong
```

---

---

Try implementing all of this code and let me know if you need more in-depth coverage of any of the topic or code.